## 错误处理 => try...catch

简介：脚本出现错误就会在错误的地方停止运行，并在控制台打印，通过`try...catch`它可以捕获错误，可以更加合理的处理错误，而不是死掉

## try...catch语法

`try...catch`结构由两部分组成：`try`和`catch`

```js
try {
	// 代码...
} catch (err) {
	// 错误捕获
}

```

它的执行顺序

1. 首先执行`try{...}`中的代码

2. 如果这里没有错误，则忽略`catch(err)`：执行到`try`的末尾并跳过`catch`继续执行

3. 如果这里出现错误，则`try`执行停止，控制流转向`catch(er)`的开头，变量`err`

   （我们这里可以使用任何名称）将包含一个`error`对象该对象包含了所发生的事件的详细信息

```js
try {
	alert(1)
	// 这里没有错误
} catch(error) {
	alert(this is error)
}		
```

```js
try {
 	alert(1)    // 执行
 	alert(foo)  // 发现一个错误,不在往下执行
 	alert(2)	// 不执行
} catch(error) {
	alert('have a error')   // 执行  错误处理
}
```

## try...catch时效性

`try...catch`的使用前提是代码是可执行的，如果代码有语法错误，那么，它将无法工作

```js
try {
	{{{}}}
} catch(e) {
	alert('this is a error')
}
```

解析：JavaScript引擎首先会读取代码，然后运行它，在读取阶段发生的错误被称为“解析时间”错误，并且无法恢复，这是因为，引擎无法理解该代码

所以：`try..catch`只能处理有效代码种出现的错误，这类错误被称为运行时错误(runtime errors)，也被称为异常(exceptions)

## try...catch同步工作

如果在异步的任务中使用，将得不到任何反馈，他就当做没有错误的略过了

```js
try{
	settimeout(()=>{
		xxxx;// 脚本将在这里停止
	},1000)
} catch(e) {
	alert('error')
}
```

以上是`try...catch`包裹着函数，该函数要稍后执行，这时引擎已经离开了`try...catch`结构

为了捕获到该函数里的错误，可以将`try...catch`放置到函数中

```js
setTimeout(()=>{
	try {
		noSuchVariable // try.. catch处理error了
	} catch {
		alert('error is caught here')
	}
},1000)
```

## Error对象

发生错误时：JavaScript生成一个包含有关其详细信息的对象，然后将该对象作为参数床底给catch

```js
tyr{
	// ...
} catch(err) {
	// error对象，也可以使用其他参数名代替
}
```

内建的error都有两个主要属性

* name：Error名称，例如，对于一个未定义的变量，名称是`ReferenceError`

* messge：Error文字描述

* stack：当前调用栈，用于调试一个字符串，其中包含有关导致error的嵌套调用序列的信息

  例如：

  ```js
  try {
  	lalala; // error
  } catch(err) {
  	alert(err.name)     // ReferenceError
  	alert(err.message)  // lalala is not defined
      alert(err.stack)    // ReferneceError:lalala is not defined at (...call stafck)
      
      // 也可以将一个error作为整体显示出来as a whole
      // Error信息被转换像"name:message"这样的字符串
      alert(err); // ReferenceError:lalala is not defin
  }
  ```

  ## 可选的catch绑定

  如果我们不需要error的详细信息，`catch`也可以忽略它

  ```js
  try {
  	// ...
  } catch {	// 没有(err)
  
  	// ...
  }
  ```

  ## 使用try...catch

  ```js
  let json = '{"name":"john","age":30}' // 来自服务器的数据
  let user = JSON.parse(json) // 将文本表示转换成JS对象
  
  // 现在user是一个解析自json字符串的有自己属性的对象
  alert(user.name) // John
  alert(user.age)  // 30
  ```

  如果，json格式错误，json.parse会生成一个error，脚本也会死亡

  如果数据出了问题，那么访问者永远都不知道原因

  ```js
  let json = '{bad json}'
  try {
  	let user = JSON.parse(json) // 会出现一个错误
  	alert(user.name) // 这里不会工作
  } catch(e) {
  	// ... 发现错误后，跳转至这里开始运作
      // 这里可以做很多事情，包括重新请求，弹框提示等
  	alert("Our apologies ,the data has errors")
  	alert(e.name)
  	alert(e.message)
  }
  ```

## 抛出自定义的error

如果这个json在语法上是正确的，但是没有所必须的`name`属性该怎么办

```js
let json = "{"age":30}" // 不完整的数据

try {
	let user = JSON.parse(json) // 没有error
	alert(user.name) // 没有name
} catch(e) {
	alert('doesn't execute)
}
```

以上代码正确，但是try中的代码错误不会被跑出来，这里要做个统一处理

`Throw`操作符

throw操作符会生成一个error对象

语法：

```js
throw <error object>
```

## try...catch...finally

```js
try {
	...尝试执行的代码
} catch(e) {
	...处理 error
} finally {
	...总会执行的代码
}
```



